Workbook

Sheet PETUNJUK
A1: DATABASE MASTER TERNAK SFI (v2)
A2: Sudah menerapkan seluruh aturan konfirmasi Anda
A5: WARNA SEL
A6: Biru | B6: Isian manual
A7: Kuning | B7: ASUMSI/perlu dilengkapi
A8: Merah | B8: Perlu konfirmasi
A9: Hijau | B9: Otomatis (rumus)
A10: Oranye | B10: Milik SFI
A12: ATURAN WARNA EARTAG
A13: Lokal / Garut / Cross / Merino / Teksel | B13: Hijau
A14: F1 | B14: Kuning
A15: F2 | B15: Orange
A16: F3 | B16: Biru
A17: Fullblood Dorper | B17: Original
A19: ATURAN GENERASI ANAKAN
A20: Indukan lokal/garut/cross/merino/teksel | B20: Anakan = F1
A21: Indukan F1 | B21: Anakan = F2
A22: Indukan F2 | B22: Anakan = F3
A23: Indukan Fullblood Dorper | B23: Anakan = PURE
A25: ATURAN PENOMORAN UNIK
B26: Format: NOMOR-MITRA (mis. 213-OKI)
B27: Bila nomor sama dipakai induk & anak: NOMOR-MITRA-INDUK / NOMOR-MITRA-ANAK
B28: Data yang DICORET di catatan tangan tidak dipakai
A30: ASUMSI YANG SAYA PAKAI (bisa Anda ubah)
A31: BB indukan belum ada | B31: 35 kg
A32: BB anakan lahir tunggal | B32: 4,5 kg
A33: BB anakan kembar 2 | B33: 3,5 kg
A34: BB anakan kembar 3 | B34: 2,5 kg
A35: Harga indukan SFI lokal | B35: Rp 4.500.000
A36: Harga indukan SFI F1 | B36: Rp 5.500.000
A37: Harga indukan SFI F2 | B37: Rp 6.500.000
A38: Harga cempe 1-3 bulan | B38: Rp 750.000
A39: Harga cempe > 3 bulan | B39: Rp 1.250.000
A40: Kandang indukan tidak melahirkan | B40: Koloni 1 & 2 (bagi rata)
A41: Kandang cempe 1-3 bulan | B41: Menyusui 1
A42: Kandang cempe > 3 bulan | B42: Penggemukan 1-4 (bagi rata)

Sheet LAPORAN ANALISA
A1: LAPORAN ANALISA PETERNAKAN
A2: SAHABAT FARM INDONESIA (SFI)
A3: Periode data: September 2025 - Juli 2026 | Disusun: 20 Juli 2026
A4: Sumber: rekonsiliasi catatan lapangan tulisan tangan dengan pembukuan digital 5 mitra
A6: 1. RINGKASAN EKSEKUTIF
A7: Total populasi ternak (hidup) | B7: 165 | C7: ekor
A8: Indukan produktif | B8: 64 | C8: ekor
A9: Anakan (cempe) hidup | B9: 101 | C9: ekor
A10: Tingkat kelangsungan hidup | B10: 99.0% | C10: sangat baik
A11: Total kelahiran tercatat | B11: 71 | C11: kali partus
A12: Rata-rata anak per kelahiran | B12: 1.44 | C12: ekor
A13: Rata-rata bobot lahir | B13: 3.70 kg | C13: dari 90 data
A14: Nilai aset ternak | B14: Rp 450.2 Juta | C14: indukan + anakan
A16: 2. STRUKTUR KEPEMILIKAN
A17: PEMILIK | B17: INDUKAN | C17: ANAKAN | D17: TOTAL | E17: % POPULASI
A18: FAHRI | B18: 5 | C18: 13 | D18: 18 | E18: 0.10843373
A19: OKI | B19: 5 | C19: 2 | D19: 7 | E19: 0.042168675
A20: LETA | B20: 5 | C20: 6 | D20: 11 | E20: 0.06626506
A21: AGENG | B21: 5 | C21: 5 | D21: 10 | E21: 0.060240964
A22: VINA | B22: 5 | C22: 17 | D22: 22 | E22: 0.13253012
A23: SFI | B23: 39 | C23: 59 | D23: 98 | E23: 0.59036145
A24: TOTAL | B24: 64 | C24: 102 | D24: 166
A26: Catatan: 59% populasi dimiliki SFI (inti), 41% dimiliki 5 mitra investor.
A28: 3. KINERJA REPRODUKSI
A29: Indukan sudah beranak | B29: 59 dari 64 ekor
A30: Tingkat keberhasilan beranak | B30: 92.2%
A31: Rata-rata anakan per indukan | B31: 1.73 ekor
A32: Rata-rata jarak antar kelahiran | B32: 133 hari
A33: Siklus per tahun (estimasi) | B33: 2.74 kali
A35: DISTRIBUSI JUMLAH ANAK PER KELAHIRAN
A36: Jumlah anak | B36: Kejadian | C36: Persentase
A37: 1 ekor (tunggal) | B37: 46 | C37: 0.64788732
A38: 2 ekor (kembar 2) | B38: 19 | C38: 0.26760563
A39: 3 ekor (kembar 3) | B39: 6 | C39: 0.084507042
A41: Analisa: 35% kelahiran menghasilkan anak kembar - indikator kesuburan yang baik untuk domba Dorper.
A43: 4. KUALITAS GENETIK (BOBOT LAHIR)
A44: Rata-rata bobot lahir | B44: 3.70 kg
A45: Bobot terendah | B45: 1.60 kg
A46: Bobot tertinggi | B46: 6.80 kg
A48: BOBOT LAHIR PER JENIS INDUKAN
...

Sheet REKAP
A1: REKAP POPULASI TERNAK SFI
A3: A. POPULASI PER PEMILIK
A4: PEMILIK | B4: INDUKAN | C4: ANAKAN | D4: HIDUP | E4: MATI | F4: NILAI INDUKAN (Rp)
A5: FAHRI | B5: =COUNTIF(INDUKAN!$E$6:$E$69,$A5) -> 5 | C5: =COUNTIF(ANAKAN!$V$6:$V$107,$A5) -> 13 | D5: =COUNTIFS(ANAKAN!$V$6:$V$107,$A5,ANAKAN!$N$6:$N$107,"Hidup") -> 13 | E5: =COUNTIFS(ANAKAN!$V$6:$V$107,$A5,ANAKAN!$N$6:$N$107,"Mati") -> 0 | F5: =SUMIF(INDUKAN!$E$6:$E$69,$A5,INDUKAN!$M$6:$M$69) -> 27500000
A6: OKI | B6: =COUNTIF(INDUKAN!$E$6:$E$69,$A6) -> 5 | C6: =COUNTIF(ANAKAN!$V$6:$V$107,$A6) -> 2 | D6: =COUNTIFS(ANAKAN!$V$6:$V$107,$A6,ANAKAN!$N$6:$N$107,"Hidup") -> 2 | E6: =COUNTIFS(ANAKAN!$V$6:$V$107,$A6,ANAKAN!$N$6:$N$107,"Mati") -> 0 | F6: =SUMIF(INDUKAN!$E$6:$E$69,$A6,INDUKAN!$M$6:$M$69) -> 32500000
A7: LETA | B7: =COUNTIF(INDUKAN!$E$6:$E$69,$A7) -> 5 | C7: =COUNTIF(ANAKAN!$V$6:$V$107,$A7) -> 6 | D7: =COUNTIFS(ANAKAN!$V$6:$V$107,$A7,ANAKAN!$N$6:$N$107,"Hidup") -> 6 | E7: =COUNTIFS(ANAKAN!$V$6:$V$107,$A7,ANAKAN!$N$6:$N$107,"Mati") -> 0 | F7: =SUMIF(INDUKAN!$E$6:$E$69,$A7,INDUKAN!$M$6:$M$69) -> 32500000
A8: AGENG | B8: =COUNTIF(INDUKAN!$E$6:$E$69,$A8) -> 5 | C8: =COUNTIF(ANAKAN!$V$6:$V$107,$A8) -> 5 | D8: =COUNTIFS(ANAKAN!$V$6:$V$107,$A8,ANAKAN!$N$6:$N$107,"Hidup") -> 5 | E8: =COUNTIFS(ANAKAN!$V$6:$V$107,$A8,ANAKAN!$N$6:$N$107,"Mati") -> 0 | F8: =SUMIF(INDUKAN!$E$6:$E$69,$A8,INDUKAN!$M$6:$M$69) -> 32500000
A9: VINA | B9: =COUNTIF(INDUKAN!$E$6:$E$69,$A9) -> 5 | C9: =COUNTIF(ANAKAN!$V$6:$V$107,$A9) -> 17 | D9: =COUNTIFS(ANAKAN!$V$6:$V$107,$A9,ANAKAN!$N$6:$N$107,"Hidup") -> 16 | E9: =COUNTIFS(ANAKAN!$V$6:$V$107,$A9,ANAKAN!$N$6:$N$107,"Mati") -> 1 | F9: =SUMIF(INDUKAN!$E$6:$E$69,$A9,INDUKAN!$M$6:$M$69) -> 27500000
A10: SFI | B10: =COUNTIF(INDUKAN!$E$6:$E$69,$A10) -> 39 | C10: =COUNTIF(ANAKAN!$V$6:$V$107,$A10) -> 59 | D10: =COUNTIFS(ANAKAN!$V$6:$V$107,$A10,ANAKAN!$N$6:$N$107,"Hidup") -> 59 | E10: =COUNTIFS(ANAKAN!$V$6:$V$107,$A10,ANAKAN!$N$6:$N$107,"Mati") -> 0 | F10: =SUMIF(INDUKAN!$E$6:$E$69,$A10,INDUKAN!$M$6:$M$69) -> 188500000
A11: TOTAL | B11: =SUM(B5:B10) -> 64 | C11: =SUM(C5:C10) -> 102 | D11: =SUM(D5:D10) -> 101 | E11: =SUM(E5:E10) -> 1 | F11: =SUM(F5:F10) -> 341000000
A13: B. STATUS TERNAK
A14: STATUS | B14: JUMLAH
A15: Cempe Lahir | B15: =COUNTIF(ANAKAN!$R$6:$R$107,$A15) -> 0
A16: Cempe Sapih | B16: =COUNTIF(ANAKAN!$S$6:$S$107,$A16) -> 0
A17: Bakalan | B17: =COUNTIF(ANAKAN!$S$6:$S$107,$A17) -> 0
A18: Dara | B18: =COUNTIF(ANAKAN!$S$6:$S$107,$A18) -> 0
A19: Jantan Siap Kawin | B19: =COUNTIF(ANAKAN!$S$6:$S$107,$A19) -> 0
A20: Betina Siap Kawin | B20: =COUNTIF(ANAKAN!$S$6:$S$107,$A20) -> 0
A22: C. GENERASI ANAKAN
A23: GENERASI | B23: JUMLAH | C23: WARNA EARTAG
A24: F1 | B24: =COUNTIF(ANAKAN!$J$6:$J$107,$A24) -> 29 | C24: Kuning
A25: F2 | B25: =COUNTIF(ANAKAN!$K$6:$K$107,$A25) -> 29 | C25: Orange
A26: F3 | B26: =COUNTIF(ANAKAN!$K$6:$K$107,$A26) -> 15 | C26: Biru
A27: F4 | B27: =COUNTIF(ANAKAN!$K$6:$K$107,$A27) -> 0 | C27: Biru
A28: PURE | B28: =COUNTIF(ANAKAN!$K$6:$K$107,$A28) -> 1 | C28: Original
A30: D. TOTAL POPULASI
A31: Total Indukan | B31: =B11 -> 64
A32: Total Anakan Hidup | B32: =D11 -> 101
A33: TOTAL TERNAK HIDUP | B33: =B11+D11 -> 165
A35: E. KUALITAS DATA
A36: Perlu dilengkapi | B36: 58
A37: BB anakan asumsi | B37: =COUNTIF(ANAKAN!$P$6:$P$107,"YA") -> 12
A38: Folder GDrive dibuat | B38: 97
A39: Indukan belum ada nomor | B39: =COUNTIF(INDUKAN!$C$6:$C$69,"BELUM ADA NO*") -> 6
A40: Anakan belum ada nomor | B40: =COUNTIF(ANAKAN!$D$6:$D$107,"BELUM ADA NO*") -> 5

Sheet INDUKAN
A1: DATA INDUKAN SFI (Mitra + Milik SFI)
J3: Tgl acuan: | L3: =TODAY() -> 46223
A5: NO | B5: TAG FINAL | C5: NOMOR | D5: TAG LAMA | E5: PEMILIK | F5: JENIS | G5: BREED (SISTEM) | H5: JENIS KELAMIN | I5: CIRI FISIK | J5: TGL LAHIR | K5: USIA (BLN) | L5: BB (KG) | M5: HARGA (Rp) | N5: KANDANG | O5: TOTAL SIKLUS | P5: TOTAL ANAKAN | Q5: ANAKAN HIDUP | R5: ANAKAN MATI | S5: LINK FOTO/VIDEO | T5: SUMBER | U5: PERLU DILENGKAPI | V5: ANAKAN TERKAIT
A6: 1 | B6: 36 | C6: 36 | E6: FAHRI | F6: F1 | G6: F1 DORPER | H6: Betina | I6: Full Blackhead ada corak putih di kepala tengah tanpa tanduk | J6: 45554 | K6: =IF($J6="","",ROUND(($L$3-$J6)/30,1)) -> 22.3 | L6: 35 | M6: 5500000 | N6: Kandang Koloni 1 | O6: 1 | P6: =COUNTIF(ANAKAN!$I$6:$I$300,$B6) -> 3 | Q6: =COUNTIFS(ANAKAN!$I$6:$I$300,$B6,ANAKAN!$N$6:$N$300,"Hidup") -> 3 | R6: =COUNTIFS(ANAKAN!$I$6:$I$300,$B6,ANAKAN!$N$6:$N$300,"Mati") -> 0 | T6: file mitra
A7: 2 | B7: 157 | C7: 157 | D7: 67 | E7: FAHRI | F7: F1 | G7: F1 DORPER | H7: Betina | I7: BlackHead ada corak hitam di punggung atas dan tanpa tanduk | J7: 45554 | K7: =IF($J7="","",ROUND(($L$3-$J7)/30,1)) -> 22.3 | L7: 35 | M7: 5500000 | N7: Kandang Koloni 2 | O7: 1 | P7: =COUNTIF(ANAKAN!$I$6:$I$300,$B7) -> 1 | Q7: =COUNTIFS(ANAKAN!$I$6:$I$300,$B7,ANAKAN!$N$6:$N$300,"Hidup") -> 1 | R7: =COUNTIFS(ANAKAN!$I$6:$I$300,$B7,ANAKAN!$N$6:$N$300,"Mati") -> 0 | T7: file mitra
A8: 3 | B8: 174 | C8: 174 | D8: 82 | E8: FAHRI | F8: F1 | G8: F1 DORPER | H8: Betina | I8: kacamata hitam sampai pipi, tanpa tanduk, atas kepala putih. | J8: 45554 | K8: =IF($J8="","",ROUND(($L$3-$J8)/30,1)) -> 22.3 | L8: 35 | M8: 5500000 | N8: Kandang Koloni 1 | O8: 2 | P8: =COUNTIF(ANAKAN!$I$6:$I$300,$B8) -> 4 | Q8: =COUNTIFS(ANAKAN!$I$6:$I$300,$B8,ANAKAN!$N$6:$N$300,"Hidup") -> 4 | R8: =COUNTIFS(ANAKAN!$I$6:$I$300,$B8,ANAKAN!$N$6:$N$300,"Mati") -> 0 | T8: file mitra
A9: 4 | B9: 161 | C9: 161 | D9: 83 | E9: FAHRI | F9: F1 | G9: F1 DORPER | H9: Betina | I9: kacamata hitam sampai pipi dan ada hitam sedikit di telinga tanpa tanduk | J9: 45554 | K9: =IF($J9="","",ROUND(($L$3-$J9)/30,1)) -> 22.3 | L9: 35 | M9: 5500000 | N9: Kandang Koloni 2 | O9: 2 | P9: =COUNTIF(ANAKAN!$I$6:$I$300,$B9) -> 2 | Q9: =COUNTIFS(ANAKAN!$I$6:$I$300,$B9,ANAKAN!$N$6:$N$300,"Hidup") -> 2 | R9: =COUNTIFS(ANAKAN!$I$6:$I$300,$B9,ANAKAN!$N$6:$N$300,"Mati") -> 0 | T9: file mitra
A10: 5 | B10: 170 | C10: 170 | D10: 192 | E10: FAHRI | F10: F1 | G10: F1 DORPER | H10: Betina | I10: Full blackhead tanpa tanduk | J10: 45554 | K10: =IF($J10="","",ROUND(($L$3-$J10)/30,1)) -> 22.3 | L10: 35 | M10: 5500000 | N10: Kandang Menyusui 1 (Individu) | O10: 2 | P10: =COUNTIF(ANAKAN!$I$6:$I$300,$B10) -> 3 | Q10: =COUNTIFS(ANAKAN!$I$6:$I$300,$B10,ANAKAN!$N$6:$N$300,"Hidup") -> 3 | R10: =COUNTIFS(ANAKAN!$I$6:$I$300,$B10,ANAKAN!$N$6:$N$300,"Mati") -> 0 | T10: file mitra
A11: 6 | B11: 213-OKI-INDUK | C11: 213 | E11: OKI | F11: F2 | G11: F2 DORPER | H11: Betina | I11: Full Blackhead tanpa tanduk | J11: 45796 | K11: =IF($J11="","",ROUND(($L$3-$J11)/30,1)) -> 14.2 | L11: 35 | M11: 6500000 | N11: Kandang Menyusui 1 (Individu) | O11: 1 | P11: =COUNTIF(ANAKAN!$I$6:$I$300,$B11) -> 1 | Q11: =COUNTIFS(ANAKAN!$I$6:$I$300,$B11,ANAKAN!$N$6:$N$300,"Hidup") -> 1 | R11: =COUNTIFS(ANAKAN!$I$6:$I$300,$B11,ANAKAN!$N$6:$N$300,"Mati") -> 0 | T11: file mitra
A12: 7 | B12: 292-OKI-INDUK | C12: 292 | E12: OKI | F12: F2 | G12: F2 DORPER | H12: Betina | I12: Full Blackhead tanpa tanduk, dan corak hitam di punggung tengah | J12: 45796 | K12: =IF($J12="","",ROUND(($L$3-$J12)/30,1)) -> 14.2 | L12: 35 | M12: 6500000 | N12: Kandang Koloni 1 | O12: 0 | P12: =COUNTIF(ANAKAN!$I$6:$I$300,$B12) -> 0 | Q12: =COUNTIFS(ANAKAN!$I$6:$I$300,$B12,ANAKAN!$N$6:$N$300,"Hidup") -> 0 | R12: =COUNTIFS(ANAKAN!$I$6:$I$300,$B12,ANAKAN!$N$6:$N$300,"Mati") -> 0 | T12: file mitra
A13: 8 | B13: 284 | C13: 284 | D13: 671 | E13: OKI | F13: F2 | G13: F2 DORPER | H13: Betina | I13: Full blackhead tanpa tanduk hingga hitam ke kedua kaki. Di sala satu kaki depan ada bagian putih di telapak | J13: 45796 | K13: =IF($J13="","",ROUND(($L$3-$J13)/30,1)) -> 14.2 | L13: 35 | M13: 6500000 | N13: Kandang Koloni 2 | O13: 0 | P13: =COUNTIF(ANAKAN!$I$6:$I$300,$B13) -> 0 | Q13: =COUNTIFS(ANAKAN!$I$6:$I$300,$B13,ANAKAN!$N$6:$N$300,"Hidup") -> 0 | R13: =COUNTIFS(ANAKAN!$I$6:$I$300,$B13,ANAKAN!$N$6:$N$300,"Mati") -> 0 | T13: file mitra
A14: 9 | B14: 277 | C14: 277 | D14: 240 | E14: OKI | F14: F2 | G14: F2 DORPER | H14: Betina | I14: full blackhead rapih badan putih | J14: 45796 | K14: =IF($J14="","",ROUND(($L$3-$J14)/30,1)) -> 14.2 | L14: 35 | M14: 6500000 | N14: Kandang Menyusui 1 (Individu) | O14: 1 | P14: =COUNTIF(ANAKAN!$I$6:$I$300,$B14) -> 1 | Q14: =COUNTIFS(ANAKAN!$I$6:$I$300,$B14,ANAKAN!$N$6:$N$300,"Hidup") -> 1 | R14: =COUNTIFS(ANAKAN!$I$6:$I$300,$B14,ANAKAN!$N$6:$N$300,"Mati") -> 0 | T14: file mitra
A15: 10 | B15: 291 | C15: 291 | D15: 290 | E15: OKI | F15: F2 | G15: F2 DORPER | H15: Betina | I15: blackhead sampai dagu. Ada corak bulat putih di kepala atas antara tanduk. | J15: 45796 | K15: =IF($J15="","",ROUND(($L$3-$J15)/30,1)) -> 14.2 | L15: 35 | M15: 6500000 | N15: Kandang Koloni 1 | O15: 0 | P15: =COUNTIF(ANAKAN!$I$6:$I$300,$B15) -> 0 | Q15: =COUNTIFS(ANAKAN!$I$6:$I$300,$B15,ANAKAN!$N$6:$N$300,"Hidup") -> 0 | R15: =COUNTIFS(ANAKAN!$I$6:$I$300,$B15,ANAKAN!$N$6:$N$300,"Mati") -> 0 | T15: file mitra
A16: 11 | B16: 268 | C16: 268 | E16: LETA | F16: F2 | G16: F2 DORPER | H16: Betina | I16: kacamata hitam sampai pipi, corak putih dari kepala sampai hidung mulut, badan full putih | J16: 45796 | K16: =IF($J16="","",ROUND(($L$3-$J16)/30,1)) -> 14.2 | L16: 35 | M16: 6500000 | N16: Kandang Menyusui 1 (Individu) | O16: 1 | P16: =COUNTIF(ANAKAN!$I$6:$I$300,$B16) -> 2 | Q16: =COUNTIFS(ANAKAN!$I$6:$I$300,$B16,ANAKAN!$N$6:$N$300,"Hidup") -> 2 | R16: =COUNTIFS(ANAKAN!$I$6:$I$300,$B16,ANAKAN!$N$6:$N$300,"Mati") -> 0 | T16: file mitra
A17: 12 | B17: 300 | C17: 300 | E17: LETA | F17: F2 | G17: F2 DORPER | H17: Betina | I17: blackhead, tanpa tanduk, corak putih di kepala atas, badan full putih | J17: 45796 | K17: =IF($J17="","",ROUND(($L$3-$J17)/30,1)) -> 14.2 | L17: 35 | M17: 6500000 | N17: Kandang Menyusui 1 (Individu) | O17: 1 | P17: =COUNTIF(ANAKAN!$I$6:$I$300,$B17) -> 2 | Q17: =COUNTIFS(ANAKAN!$I$6:$I$300,$B17,ANAKAN!$N$6:$N$300,"Hidup") -> 2 | R17: =COUNTIFS(ANAKAN!$I$6:$I$300,$B17,ANAKAN!$N$6:$N$300,"Mati") -> 0 | T17: file mitra
A18: 13 | B18: 282 | C18: 282 | D18: 235 | E18: LETA | F18: F2 | G18: F2 DORPER | H18: Betina | I18: full blackhead, badan full putih, tanpa tanduk | J18: 45796 | K18: =IF($J18="","",ROUND(($L$3-$J18)/30,1)) -> 14.2 | L18: 35 | M18: 6500000 | N18: Kandang Menyusui 1 (Individu) | O18: 1 | P18: =COUNTIF(ANAKAN!$I$6:$I$300,$B18) -> 1 | Q18: =COUNTIFS(ANAKAN!$I$6:$I$300,$B18,ANAKAN!$N$6:$N$300,"Hidup") -> 1 | R18: =COUNTIFS(ANAKAN!$I$6:$I$300,$B18,ANAKAN!$N$6:$N$300,"Mati") -> 0 | T18: file mitra
A19: 14 | B19: 270 | C19: 270 | D19: 631 | E19: LETA | F19: F2 | G19: F2 DORPER | H19: Betina | I19: full blackhead, badan full putih, sepatu hitam tanpa tanduk | J19: 45796 | K19: =IF($J19="","",ROUND(($L$3-$J19)/30,1)) -> 14.2 | L19: 35 | M19: 6500000 | N19: Kandang Koloni 2 | O19: 0 | P19: =COUNTIF(ANAKAN!$I$6:$I$300,$B19) -> 0 | Q19: =COUNTIFS(ANAKAN!$I$6:$I$300,$B19,ANAKAN!$N$6:$N$300,"Hidup") -> 0 | R19: =COUNTIFS(ANAKAN!$I$6:$I$300,$B19,ANAKAN!$N$6:$N$300,"Mati") -> 0 | T19: file mitra
A20: 15 | B20: 203 | C20: 203 | E20: LETA | F20: F2 | G20: F2 DORPER | H20: Betina | I20: full blackhead, tanpa tanduk, badan putih | J20: 45796 | K20: =IF($J20="","",ROUND(($L$3-$J20)/30,1)) -> 14.2 | L20: 35 | M20: 6500000 | N20: Kandang Menyusui 1 (Individu) | O20: 1 | P20: =COUNTIF(ANAKAN!$I$6:$I$300,$B20) -> 1 | Q20: =COUNTIFS(ANAKAN!$I$6:$I$300,$B20,ANAKAN!$N$6:$N$300,"Hidup") -> 1 | R20: =COUNTIFS(ANAKAN!$I$6:$I$300,$B20,ANAKAN!$N$6:$N$300,"Mati") -> 0 | T20: file mitra
A21: 16 | B21: 278 | C21: 278 | D21: 280 | E21: AGENG | F21: F2 | G21: F2 DORPER | H21: Betina | I21: Full Blackhead, tanpa tanduk, badan full putih | J21: 45796 | K21: =IF($J21="","",ROUND(($L$3-$J21)/30,1)) -> 14.2 | L21: 35 | M21: 6500000 | N21: Kandang Koloni 1 | O21: 0 | P21: =COUNTIF(ANAKAN!$I$6:$I$300,$B21) -> 0 | Q21: =COUNTIFS(ANAKAN!$I$6:$I$300,$B21,ANAKAN!$N$6:$N$300,"Hidup") -> 0 | R21: =COUNTIFS(ANAKAN!$I$6:$I$300,$B21,ANAKAN!$N$6:$N$300,"Mati") -> 0 | T21: file mitra
A22: 17 | B22: 281 | C22: 281 | E22: AGENG | F22: F2 | G22: F2 DORPER | H22: Betina | I22: Full Blackhead, tanpa tanduk, badan full putih. Corak putih sedikit di kepala atas. | J22: 45796 | K22: =IF($J22="","",ROUND(($L$3-$J22)/30,1)) -> 14.2 | L22: 35 | M22: 6500000 | N22: Kandang Menyusui 1 (Individu) | O22: 1 | P22: =COUNTIF(ANAKAN!$I$6:$I$300,$B22) -> 1 | Q22: =COUNTIFS(ANAKAN!$I$6:$I$300,$B22,ANAKAN!$N$6:$N$300,"Hidup") -> 1 | R22: =COUNTIFS(ANAKAN!$I$6:$I$300,$B22,ANAKAN!$N$6:$N$300,"Mati") -> 0 | T22: file mitra
A23: 18 | B23: 238 | C23: 238 | D23: 209 | E23: AGENG | F23: F2 | G23: F2 DORPER | H23: Betina | I23: full blackhead, tanpa tanduk badan putih. | J23: 45796 | K23: =IF($J23="","",ROUND(($L$3-$J23)/30,1)) -> 14.2 | L23: 35 | M23: 6500000 | N23: Kandang Menyusui 1 (Individu) | O23: 1 | P23: =COUNTIF(ANAKAN!$I$6:$I$300,$B23) -> 1 | Q23: =COUNTIFS(ANAKAN!$I$6:$I$300,$B23,ANAKAN!$N$6:$N$300,"Hidup") -> 1 | R23: =COUNTIFS(ANAKAN!$I$6:$I$300,$B23,ANAKAN!$N$6:$N$300,"Mati") -> 0 | T23: file mitra
A24: 19 | B24: 286-AGENG-INDUK | C24: 286 | E24: AGENG | F24: F2 | G24: F2 DORPER | H24: Betina | I24: black Head, corak putih di kepala atas, tanpa tanduk. Badan putih | J24: 45796 | K24: =IF($J24="","",ROUND(($L$3-$J24)/30,1)) -> 14.2 | L24: 35 | M24: 6500000 | N24: Kandang Menyusui 1 (Individu) | O24: 1 | P24: =COUNTIF(ANAKAN!$I$6:$I$300,$B24) -> 2 | Q24: =COUNTIFS(ANAKAN!$I$6:$I$300,$B24,ANAKAN!$N$6:$N$300,"Hidup") -> 2 | R24: =COUNTIFS(ANAKAN!$I$6:$I$300,$B24,ANAKAN!$N$6:$N$300,"Mati") -> 0 | T24: file mitra
A25: 20 | B25: 263 | C25: 263 | D25: 254 | E25: AGENG | F25: F2 | G25: F2 DORPER | H25: Betina | I25: BlackHead, tanpa tanduk, badan putih | J25: 45796 | K25: =IF($J25="","",ROUND(($L$3-$J25)/30,1)) -> 14.2 | L25: 35 | M25: 6500000 | N25: Kandang Menyusui 1 (Individu) | O25: 1 | P25: =COUNTIF(ANAKAN!$I$6:$I$300,$B25) -> 1 | Q25: =COUNTIFS(ANAKAN!$I$6:$I$300,$B25,ANAKAN!$N$6:$N$300,"Hidup") -> 1 | R25: =COUNTIFS(ANAKAN!$I$6:$I$300,$B25,ANAKAN!$N$6:$N$300,"Mati") -> 0 | T25: file mitra
A26: 21 | B26: 184 | C26: 184 | D26: 33 | E26: VINA | F26: F1 | G26: F1 DORPER | H26: Betina | I26: BlackHead Full, ada tanduk, ada corak putih di kepala atas putih antara tanduk | J26: 45554 | K26: =IF($J26="","",ROUND(($L$3-$J26)/30,1)) -> 22.3 | L26: 35 | M26: 5500000 | N26: Kandang Koloni 2 | O26: 1 | P26: =COUNTIF(ANAKAN!$I$6:$I$300,$B26) -> 3 | Q26: =COUNTIFS(ANAKAN!$I$6:$I$300,$B26,ANAKAN!$N$6:$N$300,"Hidup") -> 2 | R26: =COUNTIFS(ANAKAN!$I$6:$I$300,$B26,ANAKAN!$N$6:$N$300,"Mati") -> 1 | T26: file mitra
A27: 22 | B27: 87 | C27: 87 | E27: VINA | F27: F1 | G27: F1 DORPER | H27: Betina | I27: Full Blackhead tanpa tanduk | J27: 45554 | K27: =IF($J27="","",ROUND(($L$3-$J27)/30,1)) -> 22.3 | L27: 35 | M27: 5500000 | N27: Kandang Koloni 1 | O27: 1 | P27: =COUNTIF(ANAKAN!$I$6:$I$300,$B27) -> 1 | Q27: =COUNTIFS(ANAKAN!$I$6:$I$300,$B27,ANAKAN!$N$6:$N$300,"Hidup") -> 1 | R27: =COUNTIFS(ANAKAN!$I$6:$I$300,$B27,ANAKAN!$N$6:$N$300,"Mati") -> 0 | T27: file mitra
A28: 23 | B28: 171 | C28: 171 | D28: 81 | E28: VINA | F28: F1 | G28: F1 DORPER | H28: Betina | I28: Full blackhead tanpa tanduk sampai ke kaki | J28: 45554 | K28: =IF($J28="","",ROUND(($L$3-$J28)/30,1)) -> 22.3 | L28: 35 | M28: 5500000 | N28: Kandang Koloni 2 | O28: 3 | P28: =COUNTIF(ANAKAN!$I$6:$I$300,$B28) -> 7 | Q28: =COUNTIFS(ANAKAN!$I$6:$I$300,$B28,ANAKAN!$N$6:$N$300,"Hidup") -> 7 | R28: =COUNTIFS(ANAKAN!$I$6:$I$300,$B28,ANAKAN!$N$6:$N$300,"Mati") -> 0 | T28: file mitra
A29: 24 | B29: 160 | C29: 160 | D29: 75 | E29: VINA | F29: F1 | G29: F1 DORPER | H29: Betina | I29: Full white tanpa tanduk | J29: 45554 | K29: =IF($J29="","",ROUND(($L$3-$J29)/30,1)) -> 22.3 | L29: 35 | M29: 5500000 | N29: Kandang Koloni 1 | O29: 2 | P29: =COUNTIF(ANAKAN!$I$6:$I$300,$B29) -> 4 | Q29: =COUNTIFS(ANAKAN!$I$6:$I$300,$B29,ANAKAN!$N$6:$N$300,"Hidup") -> 4 | R29: =COUNTIFS(ANAKAN!$I$6:$I$300,$B29,ANAKAN!$N$6:$N$300,"Mati") -> 0 | T29: file mitra
A30: 25 | B30: 141 | C30: 141 | D30: 38 | E30: VINA | F30: F1 | G30: F1 DORPER | H30: Betina | I30: blackhead kayak kacamata satu muka tanpa tanduk | J30: 45554 | K30: =IF($J30="","",ROUND(($L$3-$J30)/30,1)) -> 22.3 | L30: 35 | M30: 5500000 | N30: Kandang Menyusui 1 (Individu) | O30: 2 | P30: =COUNTIF(ANAKAN!$I$6:$I$300,$B30) -> 2 | Q30: =COUNTIFS(ANAKAN!$I$6:$I$300,$B30,ANAKAN!$N$6:$N$300,"Hidup") -> 2 | R30: =COUNTIFS(ANAKAN!$I$6:$I$300,$B30,ANAKAN!$N$6:$N$300,"Mati") -> 0 | T30: file mitra
A31: 26 | B31: 011 | C31: 011 | E31: SFI | F31: lokal | G31: Lokal/Komposit | H31: Betina | J31: 45554 | K31: =IF($J31="","",ROUND(($L$3-$J31)/30,1)) -> 22.3 | L31: 35 | M31: 4500000 | N31: Kandang Menyusui 1 (Individu) | O31: 2 | P31: =COUNTIF(ANAKAN!$I$6:$I$300,$B31) -> 3 | Q31: =COUNTIFS(ANAKAN!$I$6:$I$300,$B31,ANAKAN!$N$6:$N$300,"Hidup") -> 3 | R31: =COUNTIFS(ANAKAN!$I$6:$I$300,$B31,ANAKAN!$N$6:$N$300,"Mati") -> 0 | T31: catatan tangan | U31: TGL LAHIR (asumsi)
A32: 27 | B32: 015 | C32: 015 | E32: SFI | F32: merino | G32: Cross Merino | H32: Betina | J32: 45554 | K32: =IF($J32="","",ROUND(($L$3-$J32)/30,1)) -> 22.3 | L32: 35 | M32: 4500000 | N32: Kandang Menyusui 1 (Individu) | O32: 1 | P32: =COUNTIF(ANAKAN!$I$6:$I$300,$B32) -> 1 | Q32: =COUNTIFS(ANAKAN!$I$6:$I$300,$B32,ANAKAN!$N$6:$N$300,"Hidup") -> 1 | R32: =COUNTIFS(ANAKAN!$I$6:$I$300,$B32,ANAKAN!$N$6:$N$300,"Mati") -> 0 | T32: catatan tangan | U32: TGL LAHIR (asumsi)
A33: 28 | B33: 019 | C33: 019 | E33: SFI | F33: lokal | G33: Lokal/Komposit | H33: Betina | J33: 45554 | K33: =IF($J33="","",ROUND(($L$3-$J33)/30,1)) -> 22.3 | L33: 35 | M33: 4500000 | N33: Kandang Menyusui 1 (Individu) | O33: 2 | P33: =COUNTIF(ANAKAN!$I$6:$I$300,$B33) -> 2 | Q33: =COUNTIFS(ANAKAN!$I$6:$I$300,$B33,ANAKAN!$N$6:$N$300,"Hidup") -> 2 | R33: =COUNTIFS(ANAKAN!$I$6:$I$300,$B33,ANAKAN!$N$6:$N$300,"Mati") -> 0 | T33: catatan tangan | U33: TGL LAHIR (asumsi)
A34: 29 | B34: 023 | C34: 023 | E34: SFI | F34: lokal | G34: Lokal/Komposit | H34: Betina | J34: 45554 | K34: =IF($J34="","",ROUND(($L$3-$J34)/30,1)) -> 22.3 | L34: 35 | M34: 4500000 | N34: Kandang Menyusui 1 (Individu) | O34: 1 | P34: =COUNTIF(ANAKAN!$I$6:$I$300,$B34) -> 2 | Q34: =COUNTIFS(ANAKAN!$I$6:$I$300,$B34,ANAKAN!$N$6:$N$300,"Hidup") -> 2 | R34: =COUNTIFS(ANAKAN!$I$6:$I$300,$B34,ANAKAN!$N$6:$N$300,"Mati") -> 0 | T34: catatan tangan | U34: TGL LAHIR (asumsi)
A35: 30 | B35: 028 | C35: 028 | E35: SFI | F35: lokal | G35: Lokal/Komposit | H35: Betina | J35: 45554 | K35: =IF($J35="","",ROUND(($L$3-$J35)/30,1)) -> 22.3 | L35: 35 | M35: 4500000 | N35: Kandang Menyusui 1 (Individu) | O35: 1 | P35: =COUNTIF(ANAKAN!$I$6:$I$300,$B35) -> 2 | Q35: =COUNTIFS(ANAKAN!$I$6:$I$300,$B35,ANAKAN!$N$6:$N$300,"Hidup") -> 2 | R35: =COUNTIFS(ANAKAN!$I$6:$I$300,$B35,ANAKAN!$N$6:$N$300,"Mati") -> 0 | T35: catatan tangan | U35: TGL LAHIR (asumsi)
A36: 31 | B36: 0338 | C36: 0338 | E36: SFI | F36: lokal | G36: Lokal/Komposit | H36: Betina | J36: 45554 | K36: =IF($J36="","",ROUND(($L$3-$J36)/30,1)) -> 22.3 | L36: 35 | M36: 4500000 | N36: Kandang Menyusui 1 (Individu) | O36: 1 | P36: =COUNTIF(ANAKAN!$I$6:$I$300,$B36) -> 1 | Q36: =COUNTIFS(ANAKAN!$I$6:$I$300,$B36,ANAKAN!$N$6:$N$300,"Hidup") -> 1 | R36: =COUNTIFS(ANAKAN!$I$6:$I$300,$B36,ANAKAN!$N$6:$N$300,"Mati") -> 0 | T36: catatan tangan | U36: TGL LAHIR (asumsi)
A37: 32 | B37: 04 | C37: 04 | E37: SFI | F37: lokal | G37: Lokal/Komposit | H37: Betina | J37: 45554 | K37: =IF($J37="","",ROUND(($L$3-$J37)/30,1)) -> 22.3 | L37: 35 | M37: 4500000 | N37: Kandang Menyusui 1 (Individu) | O37: 1 | P37: =COUNTIF(ANAKAN!$I$6:$I$300,$B37) -> 1 | Q37: =COUNTIFS(ANAKAN!$I$6:$I$300,$B37,ANAKAN!$N$6:$N$300,"Hidup") -> 1 | R37: =COUNTIFS(ANAKAN!$I$6:$I$300,$B37,ANAKAN!$N$6:$N$300,"Mati") -> 0 | T37: catatan tangan | U37: TGL LAHIR (asumsi)
A38: 33 | B38: 042 | C38: 042 | E38: SFI | F38: F1 | G38: F1 DORPER | H38: Betina | J38: 45554 | K38: =IF($J38="","",ROUND(($L$3-$J38)/30,1)) -> 22.3 | L38: 35 | M38: 5500000 | N38: Kandang Menyusui 1 (Individu) | O38: 1 | P38: =COUNTIF(ANAKAN!$I$6:$I$300,$B38) -> 3 | Q38: =COUNTIFS(ANAKAN!$I$6:$I$300,$B38,ANAKAN!$N$6:$N$300,"Hidup") -> 3 | R38: =COUNTIFS(ANAKAN!$I$6:$I$300,$B38,ANAKAN!$N$6:$N$300,"Mati") -> 0 | T38: catatan tangan | U38: TGL LAHIR (asumsi)
A39: 34 | B39: 046 | C39: 046 | E39: SFI | F39: lokal | G39: Lokal/Komposit | H39: Betina | J39: 45554 | K39: =IF($J39="","",ROUND(($L$3-$J39)/30,1)) -> 22.3 | L39: 35 | M39: 4500000 | N39: Kandang Menyusui 1 (Individu) | O39: 2 | P39: =COUNTIF(ANAKAN!$I$6:$I$300,$B39) -> 4 | Q39: =COUNTIFS(ANAKAN!$I$6:$I$300,$B39,ANAKAN!$N$6:$N$300,"Hidup") -> 4 | R39: =COUNTIFS(ANAKAN!$I$6:$I$300,$B39,ANAKAN!$N$6:$N$300,"Mati") -> 0 | T39: catatan tangan | U39: TGL LAHIR (asumsi)
A40: 35 | B40: 049 | C40: 049 | E40: SFI | F40: lokal | G40: Lokal/Komposit | H40: Betina | J40: 45554 | K40: =IF($J40="","",ROUND(($L$3-$J40)/30,1)) -> 22.3 | L40: 35 | M40: 4500000 | N40: Kandang Menyusui 1 (Individu) | O40: 1 | P40: =COUNTIF(ANAKAN!$I$6:$I$300,$B40) -> 1 | Q40: =COUNTIFS(ANAKAN!$I$6:$I$300,$B40,ANAKAN!$N$6:$N$300,"Hidup") -> 1 | R40: =COUNTIFS(ANAKAN!$I$6:$I$300,$B40,ANAKAN!$N$6:$N$300,"Mati") -> 0 | T40: catatan tangan | U40: TGL LAHIR (asumsi)
A41: 36 | B41: 056 | C41: 056 | E41: SFI | F41: lokal | G41: Lokal/Komposit | H41: Betina | J41: 45554 | K41: =IF($J41="","",ROUND(($L$3-$J41)/30,1)) -> 22.3 | L41: 35 | M41: 4500000 | N41: Kandang Menyusui 1 (Individu) | O41: 1 | P41: =COUNTIF(ANAKAN!$I$6:$I$300,$B41) -> 1 | Q41: =COUNTIFS(ANAKAN!$I$6:$I$300,$B41,ANAKAN!$N$6:$N$300,"Hidup") -> 1 | R41: =COUNTIFS(ANAKAN!$I$6:$I$300,$B41,ANAKAN!$N$6:$N$300,"Mati") -> 0 | T41: catatan tangan | U41: TGL LAHIR (asumsi)
A42: 37 | B42: 057 | C42: 057 | E42: SFI | F42: lokal | G42: Lokal/Komposit | H42: Betina | J42: 45554 | K42: =IF($J42="","",ROUND(($L$3-$J42)/30,1)) -> 22.3 | L42: 35 | M42: 4500000 | N42: Kandang Menyusui 1 (Individu) | O42: 1 | P42: =COUNTIF(ANAKAN!$I$6:$I$300,$B42) -> 1 | Q42: =COUNTIFS(ANAKAN!$I$6:$I$300,$B42,ANAKAN!$N$6:$N$300,"Hidup") -> 1 | R42: =COUNTIFS(ANAKAN!$I$6:$I$300,$B42,ANAKAN!$N$6:$N$300,"Mati") -> 0 | T42: catatan tangan | U42: TGL LAHIR (asumsi)
...

Sheet ANAKAN
A1: DATABASE ANAKAN / CEMPE SFI
P3: Tgl acuan: | R3: =TODAY() -> 46223
A5: NO | B5: TGL LAHIR | C5: TAG FINAL | D5: NOMOR AKTIF | E5: TAG LAMA | F5: TAG BARU | G5: KEMBAR | H5: IND NOMOR | I5: IND TAG FINAL | J5: IND JENIS | K5: GENERASI | L5: BREED (SISTEM) | M5: JENIS KELAMIN | N5: KONDISI | O5: BB LAHIR | P5: BB ASUMSI? | Q5: KALUNG | R5: USIA (BLN) | S5: STATUS TERNAK | T5: HARGA (Rp) | U5: KANDANG | V5: PEMILIK | W5: DI FILE MITRA | X5: LINK FOTO/VIDEO | Y5: KEYAKINAN | Z5: PERLU DILENGKAPI | AA5: CATATAN
A6: 1 | B6: 45904 | C6: C05 | D6: C05 | E6: C05 | G6: 1 | H6: 192 | I6: 170 | J6: F1 | K6: F2 | L6: F2 DORPER | M6: Betina | N6: Hidup | O6: 4.45 | Q6: Tanpa Kalung | R6: =IF($B6="","",ROUND(($Q$3-$B6)/30,1)) -> -1530.1 | S6: =IF(OR($M6="",$R6=""),"",IF($M6="Jantan",IF($R6<=3,"Cempe Lahir",IF($R6<=6,"Cempe Sapih",IF($R6<=12,"Bakalan","Jantan Siap Kawin"))),IF($M6="Betina",IF($R6<=3,"Cempe Lahir",IF($R6<=6,"Cempe Sapih",IF($R6<=8,"Dara","Betina Siap Kawin"))),""))) -> Cempe Lahir | T6: 1250000 | U6: Kandang Penggemukan 1 (Koloni) | V6: FAHRI | W6: TIDAK | Y6: sedang | Z6: no cempe C.05; indukan F1 no 192 (tulisan samping 'NO 192') | AA6: no cempe C.05; indukan F1 no 192 (tulisan samping 'NO 192')
A7: 2 | B7: 45914 | C7: B03 | D7: B03 | E7: B03 | G7: 1 | H7: 038 | I7: 141 | J7: F1 | K7: F2 | L7: F2 DORPER | M7: Betina | N7: Hidup | O7: 2.7 | Q7: Tanpa Kalung | R7: =IF($B7="","",ROUND(($Q$3-$B7)/30,1)) -> -1530.5 | S7: =IF(OR($M7="",$R7=""),"",IF($M7="Jantan",IF($R7<=3,"Cempe Lahir",IF($R7<=6,"Cempe Sapih",IF($R7<=12,"Bakalan","Jantan Siap Kawin"))),IF($M7="Betina",IF($R7<=3,"Cempe Lahir",IF($R7<=6,"Cempe Sapih",IF($R7<=8,"Dara","Betina Siap Kawin"))),""))) -> Cempe Lahir | T7: 1250000 | U7: Kandang Penggemukan 2 (Koloni) | V7: VINA | W7: TIDAK | Y7: tinggi
A8: 3 | B8: 45915 | C8: B04 | D8: B04 | E8: B04 | G8: 1 | H8: 065 | I8: 065 | J8: F1 | K8: F2 | L8: F2 DORPER | M8: Jantan | N8: Hidup | O8: 2.95 | Q8: Tanpa Kalung | R8: =IF($B8="","",ROUND(($Q$3-$B8)/30,1)) -> -1530.5 | S8: =IF(OR($M8="",$R8=""),"",IF($M8="Jantan",IF($R8<=3,"Cempe Lahir",IF($R8<=6,"Cempe Sapih",IF($R8<=12,"Bakalan","Jantan Siap Kawin"))),IF($M8="Betina",IF($R8<=3,"Cempe Lahir",IF($R8<=6,"Cempe Sapih",IF($R8<=8,"Dara","Betina Siap Kawin"))),""))) -> Cempe Lahir | T8: 1250000 | U8: Kandang Penggemukan 3 (Koloni) | V8: SFI | W8: TIDAK | Y8: tinggi
A9: 4 | B9: 45922 | C9: B05 | D9: B05 | E9: B05 | G9: 1 | H9: 900 | I9: 900 | J9: teksel | K9: F1 | L9: F1 DORPER | M9: Jantan | N9: Hidup | O9: 3.95 | Q9: Tanpa Kalung | R9: =IF($B9="","",ROUND(($Q$3-$B9)/30,1)) -> -1530.7 | S9: =IF(OR($M9="",$R9=""),"",IF($M9="Jantan",IF($R9<=3,"Cempe Lahir",IF($R9<=6,"Cempe Sapih",IF($R9<=12,"Bakalan","Jantan Siap Kawin"))),IF($M9="Betina",IF($R9<=3,"Cempe Lahir",IF($R9<=6,"Cempe Sapih",IF($R9<=8,"Dara","Betina Siap Kawin"))),""))) -> Cempe Lahir | T9: 1250000 | U9: Kandang Penggemukan 4 (Koloni) | V9: SFI | W9: TIDAK | Y9: sedang | Z9: tertulis indukan 'teksel' no 900 | AA9: tertulis indukan 'teksel' no 900
A10: 5 | B10: 45924 | C10: B06 | D10: B06 | E10: B06 | G10: 1 | H10: BELUM ADA NO-01 | I10: BELUM ADA NO-01 | J10: lokal | K10: F1 | L10: F1 DORPER | M10: Betina | N10: Hidup | O10: 4.2 | Q10: Tanpa Kalung | R10: =IF($B10="","",ROUND(($Q$3-$B10)/30,1)) -> -1530.8 | S10: =IF(OR($M10="",$R10=""),"",IF($M10="Jantan",IF($R10<=3,"Cempe Lahir",IF($R10<=6,"Cempe Sapih",IF($R10<=12,"Bakalan","Jantan Siap Kawin"))),IF($M10="Betina",IF($R10<=3,"Cempe Lahir",IF($R10<=6,"Cempe Sapih",IF($R10<=8,"Dara","Betina Siap Kawin"))),""))) -> Cempe Lahir | T10: 1250000 | U10: Kandang Penggemukan 1 (Koloni) | V10: SFI | W10: TIDAK | Y10: sedang | Z10: indukan lokal ertek - nomor tidak terbaca (ada catatan 'hila | AA10: indukan lokal ertek - nomor tidak terbaca (ada catatan 'hilang')
A11: 6 | B11: 45928 | C11: B07 | D11: B07 | E11: B07 | G11: 1 | H11: 067 | I11: 157 | J11: F1 | K11: F2 | L11: F2 DORPER | M11: Jantan | N11: Hidup | O11: 4.45 | Q11: Tanpa Kalung | R11: =IF($B11="","",ROUND(($Q$3-$B11)/30,1)) -> -1530.9 | S11: =IF(OR($M11="",$R11=""),"",IF($M11="Jantan",IF($R11<=3,"Cempe Lahir",IF($R11<=6,"Cempe Sapih",IF($R11<=12,"Bakalan","Jantan Siap Kawin"))),IF($M11="Betina",IF($R11<=3,"Cempe Lahir",IF($R11<=6,"Cempe Sapih",IF($R11<=8,"Dara","Betina Siap Kawin"))),""))) -> Cempe Lahir | T11: 1250000 | U11: Kandang Penggemukan 2 (Koloni) | V11: FAHRI | W11: YA | Y11: sedang | Z11: indukan F1 no 0?? tercoret, kemungkinan 067 | AA11: indukan F1 no 0?? tercoret, kemungkinan 067
A12: 7 | B12: 45929 | C12: B08 | D12: B08 | E12: B08 | G12: 1 | H12: BELUM ADA NO-02 | I12: BELUM ADA NO-02 | J12: lokal | K12: F1 | L12: F1 DORPER | M12: Betina | N12: Hidup | O12: 4.8 | Q12: Tanpa Kalung | R12: =IF($B12="","",ROUND(($Q$3-$B12)/30,1)) -> -1531 | S12: =IF(OR($M12="",$R12=""),"",IF($M12="Jantan",IF($R12<=3,"Cempe Lahir",IF($R12<=6,"Cempe Sapih",IF($R12<=12,"Bakalan","Jantan Siap Kawin"))),IF($M12="Betina",IF($R12<=3,"Cempe Lahir",IF($R12<=6,"Cempe Sapih",IF($R12<=8,"Dara","Betina Siap Kawin"))),""))) -> Cempe Lahir | T12: 1250000 | U12: Kandang Penggemukan 3 (Koloni) | V12: SFI | W12: TIDAK | Y12: sedang | Z12: indukan lokal, nomor tidak tertulis | AA12: indukan lokal, nomor tidak tertulis
A13: 8 | B13: 45937 | C13: 010 | D13: 010 | E13: 010 | G13: 2 | H13: 046 | I13: 046 | J13: lokal | K13: F1 | L13: F1 DORPER | M13: Betina | N13: Hidup | O13: 4 | Q13: Tanpa Kalung | R13: =IF($B13="","",ROUND(($Q$3-$B13)/30,1)) -> -1531.2 | S13: =IF(OR($M13="",$R13=""),"",IF($M13="Jantan",IF($R13<=3,"Cempe Lahir",IF($R13<=6,"Cempe Sapih",IF($R13<=12,"Bakalan","Jantan Siap Kawin"))),IF($M13="Betina",IF($R13<=3,"Cempe Lahir",IF($R13<=6,"Cempe Sapih",IF($R13<=8,"Dara","Betina Siap Kawin"))),""))) -> Cempe Lahir | T13: 1250000 | U13: Kandang Penggemukan 4 (Koloni) | V13: SFI | W13: TIDAK | Y13: sedang | Z13: NO 010 BB 4.00 - angka BB ada coretan | AA13: NO 010 BB 4.00 - angka BB ada coretan
A14: 9 | B14: 45937 | C14: 09 | D14: 09 | E14: 09 | G14: 2 | H14: 046 | I14: 046 | J14: lokal | K14: F1 | L14: F1 DORPER | M14: Jantan | N14: Hidup | O14: 3.65 | Q14: Tanpa Kalung | R14: =IF($B14="","",ROUND(($Q$3-$B14)/30,1)) -> -1531.2 | S14: =IF(OR($M14="",$R14=""),"",IF($M14="Jantan",IF($R14<=3,"Cempe Lahir",IF($R14<=6,"Cempe Sapih",IF($R14<=12,"Bakalan","Jantan Siap Kawin"))),IF($M14="Betina",IF($R14<=3,"Cempe Lahir",IF($R14<=6,"Cempe Sapih",IF($R14<=8,"Dara","Betina Siap Kawin"))),""))) -> Cempe Lahir | T14: 1250000 | U14: Kandang Penggemukan 1 (Koloni) | V14: SFI | W14: TIDAK | Y14: sedang | Z14: NO 09 BB 3.65 - angka BB ada coretan | AA14: NO 09 BB 3.65 - angka BB ada coretan
A15: 10 | B15: 45942 | C15: B11 | D15: B11 | E15: B11 | G15: 1 | H15: BELUM ADA NO-03 | I15: BELUM ADA NO-03 | J15: lokal | K15: F1 | L15: F1 DORPER | M15: Betina | N15: Hidup | O15: 3.9 | Q15: Tanpa Kalung | R15: =IF($B15="","",ROUND(($Q$3-$B15)/30,1)) -> -1531.4 | S15: =IF(OR($M15="",$R15=""),"",IF($M15="Jantan",IF($R15<=3,"Cempe Lahir",IF($R15<=6,"Cempe Sapih",IF($R15<=12,"Bakalan","Jantan Siap Kawin"))),IF($M15="Betina",IF($R15<=3,"Cempe Lahir",IF($R15<=6,"Cempe Sapih",IF($R15<=8,"Dara","Betina Siap Kawin"))),""))) -> Cempe Lahir | T15: 1250000 | U15: Kandang Penggemukan 2 (Koloni) | V15: SFI | W15: TIDAK | Y15: sedang | Z15: indukan lokal TANPA ERTEK; BB 3.90 ditulis di atas | AA15: indukan lokal TANPA ERTEK; BB 3.90 ditulis di atas
A16: 11 | B16: 45947 | C16: B12 | D16: B12 | E16: B12 | G16: 1 | H16: 0338 | I16: 0338 | J16: lokal | K16: F1 | L16: F1 DORPER | M16: Betina | N16: Hidup | O16: 2.35 | Q16: Tanpa Kalung | R16: =IF($B16="","",ROUND(($Q$3-$B16)/30,1)) -> -1531.6 | S16: =IF(OR($M16="",$R16=""),"",IF($M16="Jantan",IF($R16<=3,"Cempe Lahir",IF($R16<=6,"Cempe Sapih",IF($R16<=12,"Bakalan","Jantan Siap Kawin"))),IF($M16="Betina",IF($R16<=3,"Cempe Lahir",IF($R16<=6,"Cempe Sapih",IF($R16<=8,"Dara","Betina Siap Kawin"))),""))) -> Cempe Lahir | T16: 1250000 | U16: Kandang Penggemukan 3 (Koloni) | V16: SFI | W16: TIDAK | Y16: sedang | Z16: ertek no 0338 - digit terakhir ragu (033 atau 0338) | AA16: ertek no 0338 - digit terakhir ragu (033 atau 0338)
A17: 12 | B17: 45947 | C17: B14 | D17: B14 | E17: B14 | G17: 2 | H17: 061 | I17: 061 | J17: lokal | K17: F1 | L17: F1 DORPER | M17: Jantan | N17: Hidup | O17: 3.65 | Q17: Tanpa Kalung | R17: =IF($B17="","",ROUND(($Q$3-$B17)/30,1)) -> -1531.6 | S17: =IF(OR($M17="",$R17=""),"",IF($M17="Jantan",IF($R17<=3,"Cempe Lahir",IF($R17<=6,"Cempe Sapih",IF($R17<=12,"Bakalan","Jantan Siap Kawin"))),IF($M17="Betina",IF($R17<=3,"Cempe Lahir",IF($R17<=6,"Cempe Sapih",IF($R17<=8,"Dara","Betina Siap Kawin"))),""))) -> Cempe Lahir | T17: 1250000 | U17: Kandang Penggemukan 4 (Koloni) | V17: SFI | W17: TIDAK | Y17: sedang | Z17: lahir 2 ekor jantan bersama B13 | AA17: lahir 2 ekor jantan bersama B13
A18: 13 | B18: 45947 | C18: B13 | D18: B13 | E18: B13 | G18: 2 | H18: 061 | I18: 061 | J18: lokal | K18: F1 | L18: F1 DORPER | M18: Jantan | N18: Hidup | O18: 4.05 | Q18: Tanpa Kalung | R18: =IF($B18="","",ROUND(($Q$3-$B18)/30,1)) -> -1531.6 | S18: =IF(OR($M18="",$R18=""),"",IF($M18="Jantan",IF($R18<=3,"Cempe Lahir",IF($R18<=6,"Cempe Sapih",IF($R18<=12,"Bakalan","Jantan Siap Kawin"))),IF($M18="Betina",IF($R18<=3,"Cempe Lahir",IF($R18<=6,"Cempe Sapih",IF($R18<=8,"Dara","Betina Siap Kawin"))),""))) -> Cempe Lahir | T18: 1250000 | U18: Kandang Penggemukan 1 (Koloni) | V18: SFI | W18: TIDAK | Y18: sedang | Z18: BB tertulis 4.05 (ragu 405) | AA18: BB tertulis 4.05 (ragu 405)
A19: 14 | B19: 45954 | C19: B15 | D19: B15 | E19: B15 | G19: 1 | H19: 231 | I19: 231 | J19: F2 | K19: F3 | L19: F3 DORPER | M19: Betina | N19: Hidup | O19: 2.65 | Q19: Tanpa Kalung | R19: =IF($B19="","",ROUND(($Q$3-$B19)/30,1)) -> -1531.8 | S19: =IF(OR($M19="",$R19=""),"",IF($M19="Jantan",IF($R19<=3,"Cempe Lahir",IF($R19<=6,"Cempe Sapih",IF($R19<=12,"Bakalan","Jantan Siap Kawin"))),IF($M19="Betina",IF($R19<=3,"Cempe Lahir",IF($R19<=6,"Cempe Sapih",IF($R19<=8,"Dara","Betina Siap Kawin"))),""))) -> Cempe Lahir | T19: 1250000 | U19: Kandang Penggemukan 2 (Koloni) | V19: SFI | W19: TIDAK | Y19: tinggi
A20: 15 | B20: 45957 | C20: B16 | D20: B16 | E20: B16 | G20: 2 | H20: 081 | I20: 171 | J20: garut | K20: F1 | L20: F1 DORPER | M20: Jantan | N20: Hidup | O20: 4.4 | Q20: Tanpa Kalung | R20: =IF($B20="","",ROUND(($Q$3-$B20)/30,1)) -> -1531.9 | S20: =IF(OR($M20="",$R20=""),"",IF($M20="Jantan",IF($R20<=3,"Cempe Lahir",IF($R20<=6,"Cempe Sapih",IF($R20<=12,"Bakalan","Jantan Siap Kawin"))),IF($M20="Betina",IF($R20<=3,"Cempe Lahir",IF($R20<=6,"Cempe Sapih",IF($R20<=8,"Dara","Betina Siap Kawin"))),""))) -> Cempe Lahir | T20: 1250000 | U20: Kandang Penggemukan 3 (Koloni) | V20: VINA | W20: TIDAK | Y20: sedang | Z20: BB 4.40 (tertulis 4.40 atau 4.10) | AA20: BB 4.40 (tertulis 4.40 atau 4.10)
A21: 16 | B21: 45957 | C21: B17 | D21: B17 | E21: B17 | G21: 2 | H21: 081 | I21: 171 | J21: garut | K21: F1 | L21: F1 DORPER | M21: Betina | N21: Hidup | O21: 3.9 | Q21: Tanpa Kalung | R21: =IF($B21="","",ROUND(($Q$3-$B21)/30,1)) -> -1531.9 | S21: =IF(OR($M21="",$R21=""),"",IF($M21="Jantan",IF($R21<=3,"Cempe Lahir",IF($R21<=6,"Cempe Sapih",IF($R21<=12,"Bakalan","Jantan Siap Kawin"))),IF($M21="Betina",IF($R21<=3,"Cempe Lahir",IF($R21<=6,"Cempe Sapih",IF($R21<=8,"Dara","Betina Siap Kawin"))),""))) -> Cempe Lahir | T21: 1250000 | U21: Kandang Penggemukan 4 (Koloni) | V21: VINA | W21: TIDAK | Y21: tinggi
A22: 17 | B22: 45960 | C22: B18 | D22: B18 | E22: B18 | G22: 1 | H22: 011 | I22: 011 | J22: lokal | K22: F1 | L22: F1 DORPER | M22: Betina | N22: Hidup | O22: 4.95 | Q22: Tanpa Kalung | R22: =IF($B22="","",ROUND(($Q$3-$B22)/30,1)) -> -1532 | S22: =IF(OR($M22="",$R22=""),"",IF($M22="Jantan",IF($R22<=3,"Cempe Lahir",IF($R22<=6,"Cempe Sapih",IF($R22<=12,"Bakalan","Jantan Siap Kawin"))),IF($M22="Betina",IF($R22<=3,"Cempe Lahir",IF($R22<=6,"Cempe Sapih",IF($R22<=8,"Dara","Betina Siap Kawin"))),""))) -> Cempe Lahir | T22: 1250000 | U22: Kandang Penggemukan 1 (Koloni) | V22: SFI | W22: TIDAK | Y22: sedang | Z22: BB ditulis di atas coretan, terbaca 4.95 | AA22: BB ditulis di atas coretan, terbaca 4.95
A23: 18 | B23: 45963 | C23: B19 | D23: B19 | E23: B19 | G23: 3 | H23: 082 | I23: 174 | J23: lokal | K23: F1 | L23: F1 DORPER | M23: Jantan | N23: Hidup | O23: 2.1 | Q23: Tanpa Kalung | R23: =IF($B23="","",ROUND(($Q$3-$B23)/30,1)) -> -1532.1 | S23: =IF(OR($M23="",$R23=""),"",IF($M23="Jantan",IF($R23<=3,"Cempe Lahir",IF($R23<=6,"Cempe Sapih",IF($R23<=12,"Bakalan","Jantan Siap Kawin"))),IF($M23="Betina",IF($R23<=3,"Cempe Lahir",IF($R23<=6,"Cempe Sapih",IF($R23<=8,"Dara","Betina Siap Kawin"))),""))) -> Cempe Lahir | T23: 1250000 | U23: Kandang Penggemukan 2 (Koloni) | V23: FAHRI | W23: TIDAK | Y23: sedang | Z23: lahir 3 ekor jantan | AA23: lahir 3 ekor jantan
A24: 19 | B24: 45963 | C24: B20 | D24: B20 | E24: B20 | G24: 3 | H24: 082 | I24: 174 | J24: lokal | K24: F1 | L24: F1 DORPER | M24: Jantan | N24: Hidup | O24: 2.45 | Q24: Tanpa Kalung | R24: =IF($B24="","",ROUND(($Q$3-$B24)/30,1)) -> -1532.1 | S24: =IF(OR($M24="",$R24=""),"",IF($M24="Jantan",IF($R24<=3,"Cempe Lahir",IF($R24<=6,"Cempe Sapih",IF($R24<=12,"Bakalan","Jantan Siap Kawin"))),IF($M24="Betina",IF($R24<=3,"Cempe Lahir",IF($R24<=6,"Cempe Sapih",IF($R24<=8,"Dara","Betina Siap Kawin"))),""))) -> Cempe Lahir | T24: 1250000 | U24: Kandang Penggemukan 3 (Koloni) | V24: FAHRI | W24: TIDAK | Y24: tinggi
A25: 20 | B25: 45963 | C25: B21 | D25: B21 | E25: B21 | G25: 3 | H25: 082 | I25: 174 | J25: lokal | K25: F1 | L25: F1 DORPER | M25: Jantan | N25: Hidup | O25: 2.7 | Q25: Tanpa Kalung | R25: =IF($B25="","",ROUND(($Q$3-$B25)/30,1)) -> -1532.1 | S25: =IF(OR($M25="",$R25=""),"",IF($M25="Jantan",IF($R25<=3,"Cempe Lahir",IF($R25<=6,"Cempe Sapih",IF($R25<=12,"Bakalan","Jantan Siap Kawin"))),IF($M25="Betina",IF($R25<=3,"Cempe Lahir",IF($R25<=6,"Cempe Sapih",IF($R25<=8,"Dara","Betina Siap Kawin"))),""))) -> Cempe Lahir | T25: 1250000 | U25: Kandang Penggemukan 4 (Koloni) | V25: FAHRI | W25: TIDAK | Y25: tinggi
A26: 21 | B26: 45969 | C26: B22 | D26: B22 | E26: B22 | G26: 1 | H26: 019 | I26: 019 | J26: lokal | K26: F1 | L26: F1 DORPER | M26: Jantan | N26: Hidup | O26: 4.95 | Q26: Tanpa Kalung | R26: =IF($B26="","",ROUND(($Q$3-$B26)/30,1)) -> -1532.3 | S26: =IF(OR($M26="",$R26=""),"",IF($M26="Jantan",IF($R26<=3,"Cempe Lahir",IF($R26<=6,"Cempe Sapih",IF($R26<=12,"Bakalan","Jantan Siap Kawin"))),IF($M26="Betina",IF($R26<=3,"Cempe Lahir",IF($R26<=6,"Cempe Sapih",IF($R26<=8,"Dara","Betina Siap Kawin"))),""))) -> Cempe Lahir | T26: 1250000 | U26: Kandang Penggemukan 1 (Koloni) | V26: SFI | W26: TIDAK | Y26: tinggi
A27: 22 | B27: 45971 | C27: B23 | D27: B23 | E27: B23 | G27: 1 | H27: 099 | I27: 099-SFI-INDUK | J27: lokal | K27: F1 | L27: F1 DORPER | M27: Jantan | N27: Hidup | O27: 4.65 | Q27: Tanpa Kalung | R27: =IF($B27="","",ROUND(($Q$3-$B27)/30,1)) -> -1532.4 | S27: =IF(OR($M27="",$R27=""),"",IF($M27="Jantan",IF($R27<=3,"Cempe Lahir",IF($R27<=6,"Cempe Sapih",IF($R27<=12,"Bakalan","Jantan Siap Kawin"))),IF($M27="Betina",IF($R27<=3,"Cempe Lahir",IF($R27<=6,"Cempe Sapih",IF($R27<=8,"Dara","Betina Siap Kawin"))),""))) -> Cempe Lahir | T27: 1250000 | U27: Kandang Penggemukan 2 (Koloni) | V27: SFI | W27: TIDAK | Y27: tinggi
A28: 23 | B28: 45973 | C28: BELUM ADA NO-ANAK-01 | D28: BELUM ADA NO-ANAK-01 | G28: 1 | H28: BELUM ADA NO-04 | I28: BELUM ADA NO-04 | K28: F1 | L28: F1 DORPER | M28: Jantan | N28: Hidup | O28: 3.45 | Q28: Tanpa Kalung | R28: =IF($B28="","",ROUND(($Q$3-$B28)/30,1)) -> -1532.4 | S28: =IF(OR($M28="",$R28=""),"",IF($M28="Jantan",IF($R28<=3,"Cempe Lahir",IF($R28<=6,"Cempe Sapih",IF($R28<=12,"Bakalan","Jantan Siap Kawin"))),IF($M28="Betina",IF($R28<=3,"Cempe Lahir",IF($R28<=6,"Cempe Sapih",IF($R28<=8,"Dara","Betina Siap Kawin"))),""))) -> Cempe Lahir | T28: 1250000 | U28: Kandang Penggemukan 3 (Koloni) | V28: SFI | W28: TIDAK | Y28: rendah | Z28: NOMOR EARTAG | AA28: lahir 1 jantan BB 3.45 - INDUKAN MENINGGAL; nomor anak tidak tertulis
A29: 24 | B29: 45977 | C29: B24 | D29: B24 | E29: B24 | G29: 3 | H29: 075 | I29: 160 | J29: lokal | K29: F1 | L29: F1 DORPER | M29: Jantan | N29: Hidup | O29: 2.25 | Q29: Tanpa Kalung | R29: =IF($B29="","",ROUND(($Q$3-$B29)/30,1)) -> -1532.6 | S29: =IF(OR($M29="",$R29=""),"",IF($M29="Jantan",IF($R29<=3,"Cempe Lahir",IF($R29<=6,"Cempe Sapih",IF($R29<=12,"Bakalan","Jantan Siap Kawin"))),IF($M29="Betina",IF($R29<=3,"Cempe Lahir",IF($R29<=6,"Cempe Sapih",IF($R29<=8,"Dara","Betina Siap Kawin"))),""))) -> Cempe Lahir | T29: 1250000 | U29: Kandang Penggemukan 4 (Koloni) | V29: VINA | W29: TIDAK | Y29: tinggi | Z29: lahir 3 jantan | AA29: lahir 3 jantan
A30: 25 | B30: 45977 | C30: B25 | D30: B25 | E30: B25 | G30: 3 | H30: 075 | I30: 160 | J30: lokal | K30: F1 | L30: F1 DORPER | M30: Jantan | N30: Hidup | O30: 2.5 | Q30: Tanpa Kalung | R30: =IF($B30="","",ROUND(($Q$3-$B30)/30,1)) -> -1532.6 | S30: =IF(OR($M30="",$R30=""),"",IF($M30="Jantan",IF($R30<=3,"Cempe Lahir",IF($R30<=6,"Cempe Sapih",IF($R30<=12,"Bakalan","Jantan Siap Kawin"))),IF($M30="Betina",IF($R30<=3,"Cempe Lahir",IF($R30<=6,"Cempe Sapih",IF($R30<=8,"Dara","Betina Siap Kawin"))),""))) -> Cempe Lahir | T30: 1250000 | U30: Kandang Penggemukan 1 (Koloni) | V30: VINA | W30: TIDAK | Y30: tinggi
A31: 26 | B31: 45977 | C31: B26 | D31: B26 | E31: B26 | G31: 3 | H31: 075 | I31: 160 | J31: lokal | K31: F1 | L31: F1 DORPER | M31: Jantan | N31: Hidup | O31: 2.75 | Q31: Tanpa Kalung | R31: =IF($B31="","",ROUND(($Q$3-$B31)/30,1)) -> -1532.6 | S31: =IF(OR($M31="",$R31=""),"",IF($M31="Jantan",IF($R31<=3,"Cempe Lahir",IF($R31<=6,"Cempe Sapih",IF($R31<=12,"Bakalan","Jantan Siap Kawin"))),IF($M31="Betina",IF($R31<=3,"Cempe Lahir",IF($R31<=6,"Cempe Sapih",IF($R31<=8,"Dara","Betina Siap Kawin"))),""))) -> Cempe Lahir | T31: 1250000 | U31: Kandang Penggemukan 2 (Koloni) | V31: VINA | W31: TIDAK | Y31: tinggi
A32: 27 | B32: 45979 | C32: B27 | D32: B27 | E32: B27 | G32: 1 | H32: 083 | I32: 161 | J32: lokal | K32: F1 | L32: F1 DORPER | M32: Betina | N32: Hidup | O32: 3.9 | Q32: Tanpa Kalung | R32: =IF($B32="","",ROUND(($Q$3-$B32)/30,1)) -> -1532.6 | S32: =IF(OR($M32="",$R32=""),"",IF($M32="Jantan",IF($R32<=3,"Cempe Lahir",IF($R32<=6,"Cempe Sapih",IF($R32<=12,"Bakalan","Jantan Siap Kawin"))),IF($M32="Betina",IF($R32<=3,"Cempe Lahir",IF($R32<=6,"Cempe Sapih",IF($R32<=8,"Dara","Betina Siap Kawin"))),""))) -> Cempe Lahir | T32: 1250000 | U32: Kandang Penggemukan 3 (Koloni) | V32: FAHRI | W32: TIDAK | Y32: sedang | Z32: BB terbaca 3.90 (ada coretan 3.?0) | AA32: BB terbaca 3.90 (ada coretan 3.?0)
A33: 28 | B33: 45979 | C33: B28 | D33: B28 | E33: B28 | G33: 1 | H33: 084 | I33: 084 | J33: lokal | K33: F1 | L33: F1 DORPER | M33: Betina | N33: Hidup | O33: 4.5 | Q33: Tanpa Kalung | R33: =IF($B33="","",ROUND(($Q$3-$B33)/30,1)) -> -1532.6 | S33: =IF(OR($M33="",$R33=""),"",IF($M33="Jantan",IF($R33<=3,"Cempe Lahir",IF($R33<=6,"Cempe Sapih",IF($R33<=12,"Bakalan","Jantan Siap Kawin"))),IF($M33="Betina",IF($R33<=3,"Cempe Lahir",IF($R33<=6,"Cempe Sapih",IF($R33<=8,"Dara","Betina Siap Kawin"))),""))) -> Cempe Lahir | T33: 1250000 | U33: Kandang Penggemukan 4 (Koloni) | V33: SFI | W33: TIDAK | Y33: sedang | Z33: indukan lokal ertek no 0?4 - kemungkinan 084 | AA33: indukan lokal ertek no 0?4 - kemungkinan 084
A34: 29 | B34: 45983 | C34: B29 | D34: B29 | E34: B29 | G34: 2 | H34: 081 | I34: 171 | J34: F1 | K34: F2 | L34: F2 DORPER | M34: Betina | N34: Hidup | O34: 1.75 | Q34: Pink | R34: =IF($B34="","",ROUND(($Q$3-$B34)/30,1)) -> -1532.8 | S34: =IF(OR($M34="",$R34=""),"",IF($M34="Jantan",IF($R34<=3,"Cempe Lahir",IF($R34<=6,"Cempe Sapih",IF($R34<=12,"Bakalan","Jantan Siap Kawin"))),IF($M34="Betina",IF($R34<=3,"Cempe Lahir",IF($R34<=6,"Cempe Sapih",IF($R34<=8,"Dara","Betina Siap Kawin"))),""))) -> Cempe Lahir | T34: 1250000 | U34: Kandang Penggemukan 1 (Koloni) | V34: VINA | W34: YA | Y34: tinggi | Z34: lahir 2 ekor betina; milik VINA | AA34: lahir 2 ekor betina; milik VINA
A35: 30 | B35: 45983 | C35: B30 | D35: B30 | E35: B30 | G35: 2 | H35: 081 | I35: 171 | J35: F1 | K35: F2 | L35: F2 DORPER | M35: Betina | N35: Hidup | O35: 2.85 | Q35: Pink | R35: =IF($B35="","",ROUND(($Q$3-$B35)/30,1)) -> -1532.8 | S35: =IF(OR($M35="",$R35=""),"",IF($M35="Jantan",IF($R35<=3,"Cempe Lahir",IF($R35<=6,"Cempe Sapih",IF($R35<=12,"Bakalan","Jantan Siap Kawin"))),IF($M35="Betina",IF($R35<=3,"Cempe Lahir",IF($R35<=6,"Cempe Sapih",IF($R35<=8,"Dara","Betina Siap Kawin"))),""))) -> Cempe Lahir | T35: 1250000 | U35: Kandang Penggemukan 2 (Koloni) | V35: VINA | W35: YA | Y35: tinggi | Z35: milik VINA | AA35: milik VINA
A36: 31 | B36: 45984 | C36: B31 | D36: B31 | E36: B31 | G36: 3 | H36: 036 | I36: 36 | J36: F1 | K36: F2 | L36: F2 DORPER | M36: Betina | N36: Hidup | O36: 1.8 | Q36: Hijau | R36: =IF($B36="","",ROUND(($Q$3-$B36)/30,1)) -> -1532.8 | S36: =IF(OR($M36="",$R36=""),"",IF($M36="Jantan",IF($R36<=3,"Cempe Lahir",IF($R36<=6,"Cempe Sapih",IF($R36<=12,"Bakalan","Jantan Siap Kawin"))),IF($M36="Betina",IF($R36<=3,"Cempe Lahir",IF($R36<=6,"Cempe Sapih",IF($R36<=8,"Dara","Betina Siap Kawin"))),""))) -> Cempe Lahir | T36: 1250000 | U36: Kandang Penggemukan 3 (Koloni) | V36: FAHRI | W36: YA | Y36: tinggi | Z36: lahir 3 ekor; milik FAHRI | AA36: lahir 3 ekor; milik FAHRI
A37: 32 | B37: 45984 | C37: B32 | D37: B32 | E37: B32 | G37: 3 | H37: 036 | I37: 36 | J37: F1 | K37: F2 | L37: F2 DORPER | M37: Betina | N37: Hidup | O37: 2.45 | Q37: Hijau | R37: =IF($B37="","",ROUND(($Q$3-$B37)/30,1)) -> -1532.8 | S37: =IF(OR($M37="",$R37=""),"",IF($M37="Jantan",IF($R37<=3,"Cempe Lahir",IF($R37<=6,"Cempe Sapih",IF($R37<=12,"Bakalan","Jantan Siap Kawin"))),IF($M37="Betina",IF($R37<=3,"Cempe Lahir",IF($R37<=6,"Cempe Sapih",IF($R37<=8,"Dara","Betina Siap Kawin"))),""))) -> Cempe Lahir | T37: 1250000 | U37: Kandang Penggemukan 4 (Koloni) | V37: FAHRI | W37: YA | Y37: tinggi | Z37: milik FAHRI | AA37: milik FAHRI
A38: 33 | B38: 45984 | C38: B33 | D38: B33 | E38: B33 | G38: 3 | H38: 036 | I38: 36 | J38: F1 | K38: F2 | L38: F2 DORPER | M38: Jantan | N38: Hidup | O38: 2.65 | Q38: Hijau | R38: =IF($B38="","",ROUND(($Q$3-$B38)/30,1)) -> -1532.8 | S38: =IF(OR($M38="",$R38=""),"",IF($M38="Jantan",IF($R38<=3,"Cempe Lahir",IF($R38<=6,"Cempe Sapih",IF($R38<=12,"Bakalan","Jantan Siap Kawin"))),IF($M38="Betina",IF($R38<=3,"Cempe Lahir",IF($R38<=6,"Cempe Sapih",IF($R38<=8,"Dara","Betina Siap Kawin"))),""))) -> Cempe Lahir | T38: 1250000 | U38: Kandang Penggemukan 1 (Koloni) | V38: FAHRI | W38: YA | Y38: tinggi | Z38: milik FAHRI | AA38: milik FAHRI
A39: 34 | B39: 45985 | C39: B34 | D39: B34 | E39: B34 | G39: 1 | H39: 083 | I39: 161 | J39: F1 | K39: F2 | L39: F2 DORPER | M39: Jantan | N39: Hidup | O39: 3.95 | Q39: Hijau | R39: =IF($B39="","",ROUND(($Q$3-$B39)/30,1)) -> -1532.8 | S39: =IF(OR($M39="",$R39=""),"",IF($M39="Jantan",IF($R39<=3,"Cempe Lahir",IF($R39<=6,"Cempe Sapih",IF($R39<=12,"Bakalan","Jantan Siap Kawin"))),IF($M39="Betina",IF($R39<=3,"Cempe Lahir",IF($R39<=6,"Cempe Sapih",IF($R39<=8,"Dara","Betina Siap Kawin"))),""))) -> Cempe Lahir | T39: 1250000 | U39: Kandang Penggemukan 2 (Koloni) | V39: FAHRI | W39: YA | Y39: sedang | Z39: ertek indukan ada coretan, terbaca 083 | AA39: ertek indukan ada coretan, terbaca 083
A40: 35 | B40: 45986 | C40: B35 | D40: B35 | E40: B35 | G40: 3 | H40: 042 | I40: 042 | J40: F1 | K40: F2 | L40: F2 DORPER | M40: Betina | N40: Hidup | O40: 2.9 | Q40: Biru | R40: =IF($B40="","",ROUND(($Q$3-$B40)/30,1)) -> -1532.9 | S40: =IF(OR($M40="",$R40=""),"",IF($M40="Jantan",IF($R40<=3,"Cempe Lahir",IF($R40<=6,"Cempe Sapih",IF($R40<=12,"Bakalan","Jantan Siap Kawin"))),IF($M40="Betina",IF($R40<=3,"Cempe Lahir",IF($R40<=6,"Cempe Sapih",IF($R40<=8,"Dara","Betina Siap Kawin"))),""))) -> Cempe Lahir | T40: 1250000 | U40: Kandang Penggemukan 3 (Koloni) | V40: SFI | W40: TIDAK | Y40: sedang | Z40: JENIS KELAMIN (asumsi) | AA40: lahir 3 ekor kalung biru; JK tidak tertulis
A41: 36 | B41: 45986 | C41: B36 | D41: B36 | E41: B36 | G41: 3 | H41: 042 | I41: 042 | J41: F1 | K41: F2 | L41: F2 DORPER | M41: Betina | N41: Hidup | O41: 3.05 | Q41: Biru | R41: =IF($B41="","",ROUND(($Q$3-$B41)/30,1)) -> -1532.9 | S41: =IF(OR($M41="",$R41=""),"",IF($M41="Jantan",IF($R41<=3,"Cempe Lahir",IF($R41<=6,"Cempe Sapih",IF($R41<=12,"Bakalan","Jantan Siap Kawin"))),IF($M41="Betina",IF($R41<=3,"Cempe Lahir",IF($R41<=6,"Cempe Sapih",IF($R41<=8,"Dara","Betina Siap Kawin"))),""))) -> Cempe Lahir | T41: 1250000 | U41: Kandang Penggemukan 4 (Koloni) | V41: SFI | W41: TIDAK | Y41: sedang | Z41: JENIS KELAMIN (asumsi) | AA41: JK tidak tertulis
A42: 37 | B42: 45986 | C42: B37 | D42: B37 | E42: B37 | G42: 3 | H42: 042 | I42: 042 | J42: F1 | K42: F2 | L42: F2 DORPER | M42: Betina | N42: Hidup | O42: 2.95 | Q42: Biru | R42: =IF($B42="","",ROUND(($Q$3-$B42)/30,1)) -> -1532.9 | S42: =IF(OR($M42="",$R42=""),"",IF($M42="Jantan",IF($R42<=3,"Cempe Lahir",IF($R42<=6,"Cempe Sapih",IF($R42<=12,"Bakalan","Jantan Siap Kawin"))),IF($M42="Betina",IF($R42<=3,"Cempe Lahir",IF($R42<=6,"Cempe Sapih",IF($R42<=8,"Dara","Betina Siap Kawin"))),""))) -> Cempe Lahir | T42: 1250000 | U42: Kandang Penggemukan 1 (Koloni) | V42: SFI | W42: TIDAK | Y42: sedang | Z42: JENIS KELAMIN (asumsi) | AA42: JK tidak tertulis
...

Sheet HISTORI EARTAG
A1: HISTORI PENGGANTIAN EARTAG
A2: Nomor AWAL = nomor LAMA. Satu ekor bisa punya beberapa nomor - jangan dihitung dua kali.
A4: NO | B4: TAG LAMA | C4: TAG BARU | D4: RANTAI | E4: TAG FINAL | F4: JENIS INDUKAN | G4: GENERASI ANAK | H4: TGL LAHIR | I4: PEMILIK | J4: KEYAKINAN | K4: CATATAN
A5: 1 | B5: F19 | C5: 212 | D5: =$B5&" > "&$C5 -> F19 > 212 | E5: 212-SFI | F5: lokal | G5: F1 | H5: 46136 | I5: SFI | J5: tinggi | K5: indukan lokal
A6: 2 | B6: F13 | C6: 478 | D6: =$B6&" > "&$C6 -> F13 > 478 | E6: 478-LETA | F6: F2 | G6: F3 | H6: 46124 | I6: LETA | J6: tinggi
A7: 3 | B7: F07 | C7: 397 | D7: =$B7&" > "&$C7 -> F07 > 397 | E7: 397-FAHRI | F7: F1 | G7: F2 | H7: 46123 | I7: FAHRI | J7: tinggi
A8: 4 | B8: F11 | C8: 233 | D8: =$B8&" > "&$C8 -> F11 > 233 | E8: 233-SFI | F8: Teksel | G8: F1 | H8: 46123 | I8: SFI | J8: tinggi
A9: 5 | B9: F06 | C9: 399 | D9: =$B9&" > "&$C9 -> F06 > 399 | E9: 399-FAHRI | F9: F1 | G9: F2 | H9: 46123 | I9: FAHRI | J9: tinggi
A10: 6 | B10: F10 | C10: 229 | D10: =$B10&" > "&$C10 -> F10 > 229 | E10: 229-SFI | F10: Teksel | G10: F1 | H10: 46123 | I10: SFI | J10: tinggi
A11: 7 | B11: F21 | C11: 302 | D11: =$B11&" > "&$C11 -> F21 > 302 | E11: 302-VINA | F11: F1 | G11: F2 | H11: 46149 | I11: VINA | J11: tinggi
A12: 8 | B12: F23 | C12: 485 | D12: =$B12&" > "&$C12 -> F23 > 485 | F12: F2 | J12: tinggi
A13: 9 | B13: F25 | C13: 240 | D13: =$B13&" > "&$C13 -> F25 > 240 | E13: 240-SFI | F13: lokal | G13: F1 | H13: 46161 | I13: SFI | J13: tinggi
A14: 10 | B14: F14 | C14: 497 | D14: =$B14&" > "&$C14 -> F14 > 497 | E14: 497-LETA | F14: F2 | G14: F3 | H14: 46126 | I14: LETA | J14: tinggi
A15: 11 | B15: F22 | C15: 216 | D15: =$B15&" > "&$C15 -> F22 > 216 | E15: 216-SFI | F15: lokal | G15: F1 | H15: 46151 | I15: SFI | J15: tinggi
A16: 12 | B16: A73 | C16: 228 | D16: =$B16&" > "&$C16 -> A73 > 228 | E16: 228-SFI | F16: lokal | G16: F1 | H16: 46165 | I16: SFI | J16: tinggi
A17: 13 | B17: A58 | C17: 239 | D17: =$B17&" > "&$C17 -> A58 > 239 | E17: 239-VINA | F17: garut lokal | G17: F1 | H17: 46165 | I17: VINA | J17: tinggi
A18: 14 | B18: A54 | C18: 425 | D18: =$B18&" > "&$C18 -> A54 > 425 | F18: F2 | J18: tinggi
A19: 15 | B19: A55 | C19: 495 | D19: =$B19&" > "&$C19 -> A55 > 495 | E19: 495-AGENG | F19: F2 | G19: F3 | H19: 46164 | I19: AGENG | J19: tinggi
A20: 16 | B20: F12 | C20: 406 | D20: =$B20&" > "&$C20 -> F12 > 406 | E20: 406-LETA | F20: F2 | G20: F3 | H20: 46124 | I20: LETA | J20: tinggi
A21: 17 | B21: A74 | C21: 496 | D21: =$B21&" > "&$C21 -> A74 > 496 | E21: 496-OKI | F21: F2 | G21: F3 | H21: 46165 | I21: OKI | J21: sedang | K21: angka dalam kurung bisa 496 atau 896
A22: 18 | B22: F17 | C22: 489 | D22: =$B22&" > "&$C22 -> F17 > 489 | E22: 489-LETA | F22: F2 | G22: F3 | H22: 46135 | I22: LETA | J22: tinggi
A23: 19 | B23: F15 | C23: 498 | D23: =$B23&" > "&$C23 -> F15 > 498 | E23: 498-AGENG | F23: F2 | G23: F3 | H23: 46133 | I23: AGENG | J23: tinggi
A24: 20 | B24: A57 | C24: 220 | D24: =$B24&" > "&$C24 -> A57 > 220 | E24: 220-VINA | F24: garut lokal | G24: F1 | H24: 46165 | I24: VINA | J24: tinggi
A25: 21 | B25: F08 | C25: 217 | D25: =$B25&" > "&$C25 -> F08 > 217 | E25: 217-SFI | F25: lokal | G25: F1 | H25: 46123 | I25: SFI | J25: tinggi
A26: 22 | B26: F24 | C26: 484 | D26: =$B26&" > "&$C26 -> F24 > 484 | E26: 484-AGENG | F26: F2 | G26: F3 | H26: 46153 | I26: AGENG | J26: tinggi
A27: 23 | B27: F16 | C27: 500 | D27: =$B27&" > "&$C27 -> F16 > 500 | E27: 500-AGENG | F27: F2 | G27: F3 | H27: 46133 | I27: AGENG | J27: tinggi
A28: 24 | B28: A56 | C28: 208 | D28: =$B28&" > "&$C28 -> A56 > 208 | E28: 208-VINA | F28: garut lokal | G28: F1 | H28: 46165 | I28: VINA | J28: tinggi
A29: 25 | B29: F18 | C29: 409 | D29: =$B29&" > "&$C29 -> F18 > 409 | E29: 409-LETA | F29: F2 | G29: F3 | H29: 46135 | I29: LETA | J29: tinggi
A30: 26 | B30: F09 | C30: 099 | D30: =$B30&" > "&$C30 -> F09 > 099 | E30: 099-SFI-ANAK | F30: FB | G30: PURE | H30: 46123 | I30: SFI | J30: rendah | K30: baris kedua tertulis (098) yg beli - perlu konfirmasi
A31: 27 | B31: A88 | C31: 219 | D31: =$B31&" > "&$C31 -> A88 > 219 | E31: 219-SFI | F31: lokal | G31: F1 | H31: 46189 | I31: SFI | J31: tinggi
A32: 28 | B32: A81 | C32: 224 | D32: =$B32&" > "&$C32 -> A81 > 224 | E32: 224-SFI | F32: lokal | G32: F1 | H32: 46167 | I32: SFI | J32: tinggi
A33: 29 | B33: A82 | C33: 285 | D33: =$B33&" > "&$C33 -> A82 > 285 | E33: 285-SFI | F33: lokal | G33: F1 | H33: 46177 | I33: SFI | J33: tinggi
A34: 30 | B34: A76 | C34: 214 | D34: =$B34&" > "&$C34 -> A76 > 214 | E34: 214-SFI | F34: lokal | G34: F1 | H34: 46170 | I34: SFI | J34: tinggi
A35: 31 | B35: A85 | C35: 292 | D35: =$B35&" > "&$C35 -> A85 > 292 | E35: 292-SFI-ANAK | F35: lokal | G35: F1 | H35: 46179 | I35: SFI | J35: tinggi
A36: 32 | B36: A90 | C36: 293 | D36: =$B36&" > "&$C36 -> A90 > 293 | F36: lokal | J36: tinggi
A37: 33 | B37: A89 | C37: 291 | D37: =$B37&" > "&$C37 -> A89 > 291 | F37: lokal | J37: tinggi
A38: 34 | B38: A87 | C38: 479 | D38: =$B38&" > "&$C38 -> A87 > 479 | E38: 479-OKI | F38: F2 | G38: F3 | H38: 46188 | I38: OKI | J38: tinggi
A39: 35 | B39: A79 | C39: 309 | D39: =$B39&" > "&$C39 -> A79 > 309 | E39: 309-SFI | F39: F1 | G39: F2 | H39: 46170 | I39: SFI | J39: tinggi
A40: 36 | B40: A75 | C40: 295 | D40: =$B40&" > "&$C40 -> A75 > 295 | E40: 295-SFI | F40: lokal | G40: F1 | H40: 46169 | I40: SFI | J40: tinggi
A41: 37 | B41: A53 | C41: 388 | D41: =$B41&" > "&$C41 -> A53 > 388 | E41: 388-SFI | F41: F1 | G41: F2 | H41: 46162 | I41: SFI | J41: tinggi
...

Sheet FOLDER GDRIVE
A1: STRUKTUR FOLDER GOOGLE DRIVE - TERNAK MILIK SFI
A2: Jalankan file BUAT_FOLDER_GDRIVE.gs di script.google.com untuk membuat 96 folder ini otomatis, lalu tempel link hasilnya di kolom LINK.
A4: NO | B4: LEVEL | C4: NAMA FOLDER | D4: PATH LENGKAP | E4: KETERANGAN | F4: LINK GDRIVE (tempel di sini)
A5: 1 | B5: 1 | C5: SFI - DOKUMENTASI TERNAK | D5: SFI - DOKUMENTASI TERNAK | E5: Folder induk (root)
A6: 2 | B6: 2 | C6: 01 INDUKAN SFI | D6: SFI - DOKUMENTASI TERNAK/01 INDUKAN SFI | E6: Semua indukan milik SFI
A7: 3 | B7: 3 | C7: 011-SFI | D7: SFI - DOKUMENTASI TERNAK/01 INDUKAN SFI/011-SFI | E7: Indukan lokal - eartag Hijau
A8: 4 | B8: 3 | C8: 015-SFI | D8: SFI - DOKUMENTASI TERNAK/01 INDUKAN SFI/015-SFI | E8: Indukan merino - eartag Hijau
A9: 5 | B9: 3 | C9: 019-SFI | D9: SFI - DOKUMENTASI TERNAK/01 INDUKAN SFI/019-SFI | E9: Indukan lokal - eartag Hijau
A10: 6 | B10: 3 | C10: 023-SFI | D10: SFI - DOKUMENTASI TERNAK/01 INDUKAN SFI/023-SFI | E10: Indukan lokal - eartag Hijau
A11: 7 | B11: 3 | C11: 028-SFI | D11: SFI - DOKUMENTASI TERNAK/01 INDUKAN SFI/028-SFI | E11: Indukan lokal - eartag Hijau
A12: 8 | B12: 3 | C12: 0338-SFI | D12: SFI - DOKUMENTASI TERNAK/01 INDUKAN SFI/0338-SFI | E12: Indukan lokal - eartag Hijau
A13: 9 | B13: 3 | C13: 04-SFI | D13: SFI - DOKUMENTASI TERNAK/01 INDUKAN SFI/04-SFI | E13: Indukan lokal - eartag Hijau
A14: 10 | B14: 3 | C14: 042-SFI | D14: SFI - DOKUMENTASI TERNAK/01 INDUKAN SFI/042-SFI | E14: Indukan F1 - eartag Kuning
A15: 11 | B15: 3 | C15: 046-SFI | D15: SFI - DOKUMENTASI TERNAK/01 INDUKAN SFI/046-SFI | E15: Indukan lokal - eartag Hijau
A16: 12 | B16: 3 | C16: 049-SFI | D16: SFI - DOKUMENTASI TERNAK/01 INDUKAN SFI/049-SFI | E16: Indukan lokal - eartag Hijau
... A101: 97 | B101: 4 | C101: 294-SFI | D101: SFI - DOKUMENTASI TERNAK/02 ANAKAN SFI/2026-06/294-SFI | E101: Lahir 2026-06-04 - Jantan - indukan 011

Sheet PERLU KONFIRMASI
A1: SISA YANG PERLU ANDA LENGKAPI
A2: Lima poin sebelumnya sudah diterapkan. Ini sisanya.
A4: NO | B4: KATEGORI | C4: TAG | D4: TANGGAL | E4: MASALAH | F4: JAWABAN ANDA
A5: 1 | B5: Jenis kelamin belum ada | C5: B35-SFI | D5: 45986 | E5: JK tidak tertulis di catatan tangan
A6: 2 | B6: Jenis kelamin belum ada | C6: B36-SFI | D6: 45986 | E6: JK tidak tertulis di catatan tangan
A7: 3 | B7: Jenis kelamin belum ada | C7: B37-SFI | D7: 45986 | E7: JK tidak tertulis di catatan tangan
A8: 4 | B8: Jenis kelamin belum ada | C8: B41-VINA | D8: 45992 | E8: JK tidak tertulis di catatan tangan
A9: 5 | B9: Jenis kelamin belum ada | C9: B42-VINA | D9: 45992 | E9: JK tidak tertulis di catatan tangan
A10: 6 | B10: Nomor eartag belum ada | C10: (kosong) | D10: 45973 | E10: Jantan dari indukan ?
A11: 7 | B11: Nomor eartag belum ada | C11: (kosong) | D11: 46019 | E11: Betina dari indukan 049
A12: 8 | B12: Nomor eartag belum ada | C12: (kosong) | D12: 46019 | E12: Jantan dari indukan 04
A13: 9 | B13: Nomor eartag belum ada | C13: (kosong) | D13: 46019 | E13: Betina dari indukan 057
A14: 10 | B14: Nomor eartag belum ada | C14: (kosong) | D14: 46020 | E14: Jantan dari indukan 676
A15: 11 | B15: Tgl lahir indukan belum ada | C15: 213-OKI-INDUK | E15: Indukan F2 milik OKI
A16: 12 | B16: Tgl lahir indukan belum ada | C16: 292-OKI-INDUK | E16: Indukan F2 milik OKI
A17: 13 | B17: Tgl lahir indukan belum ada | C17: 284-OKI | E17: Indukan F2 milik OKI
A18: 14 | B18: Tgl lahir indukan belum ada | C18: 277-OKI | E18: Indukan F2 milik OKI
A19: 15 | B19: Tgl lahir indukan belum ada | C19: 291-OKI | E19: Indukan F2 milik OKI
A20: 16 | B20: Tgl lahir indukan belum ada | C20: 011-SFI | E20: Indukan lokal milik SFI
A21: 17 | B21: Tgl lahir indukan belum ada | C21: 015-SFI | E21: Indukan merino milik SFI
A22: 18 | B22: Tgl lahir indukan belum ada | C22: 019-SFI | E22: Indukan lokal milik SFI
